Workbook

Sheet Casuística
C1: DADOS DEMOGRÁFICOS | G1: REGIME E ESPECIALIDADE | J1: DIAGNÓSTICO E PROCEDIMENTO | N1: TÉCNICA ANESTÉSICA | P1: NEUROEIXO | T1: BLOQUEIOS PERIFÉRICOS | Y1: MONITORIZAÇÃO | Z1: VIA AÉREA | AE1: DISPOSITIVOS | AK1: EVOLUÇÃO
A2: Data | B2: NP | C2: Idade | D2: Grupo Etário | E2: Sexo | F2: ASA | G2: Regime | H2: Especialidade | I2: Local fora do BO | J2: Diagnóstico | K2: Particularidades | L2: Procedimento | M2: Duração | N2: Técnica Anestésica | O2: Anestesia Geral | P2: Neuroeixo | Q2: Método | R2: Intuito | S2: Sucesso | T2: Bloqueio Periférico 1 | U2: Bloqueio Periférico 2 | V2: Método | W2: Intuito | X2: Sucesso | Y2: Monitorização | Z2: Tipo VA | AA2: Técnica VA | AB2: Laringoscópio e Adjuvantes | AC2: Cormack-Lehane | AD2: Sucesso VA | AE2: Linha Arterial | AF2: Método LA | AG2: Sucesso LA | AH2: CVC | AI2: Método CVC | AJ2: Sucesso CVC | AK2: Destino | AL2: Complicações | AM2: Caso complexo | AN2: Observações

Sheet Tabela Atividade
A1: Formato da Tabela 18 do RAA – atividade em regime de urgência
C3: TOTAL
A4: Atividade dentro do BO | C4: =COUNTA('Casuística'!$H$3:$H$302)-COUNTIFS('Casuística'!$H$3:$H$302,"=Fora do Bloco")-COUNTIFS('Casuística'!$H$3:$H$302,"=Doente Crítico")
A5: Atividade fora do BO | C5: =C6+C7
A6: Doente Crítico | C6: =COUNTIFS('Casuística'!$H$3:$H$302,"=Doente Crítico")
A7: Unidade de Técnicas de Gastroenterologia | C7: =COUNTIFS('Casuística'!$H$3:$H$302,"=Fora do Bloco",'Casuística'!$I$3:$I$302,"=Gastroenterologia")
A8: TOTAL | C8: =C4+C5
A10: Doente Crítico – detalhe
A11: Procedimento | B11: Local | C11: Data
A12: DC | C12: 46028
A13: entubacao OT para traqueo eventual se necessário | B13: UCI Pediátrica | C13: 46046
A14: levar à tc pós op | C14: 46054
A15: Estabilizar | C15: 46109

Sheet Tabela Relatório
A1: Formato da Tabela 19 do RAA (atos anestésicos; o doente crítico fica na Tabela Atividade). Cada coluna soma-se à coluna da mesma especialidade na casuística global (Tabela 2); "Fora do Bloco" soma-se a AFBO.
A3: ANESTESIOLOGIA DE URGÊNCIA | D3: C. Geral | E3: C. Pediátrica | F3: C. Plástica | G3: C. Vascular | H3: Ginecologia | I3: Neurocirurgia | J3: Oftalmologia | K3: ORL | L3: Ortopedia | M3: Urologia | N3: U.T. Gastro / Fora do BO | O3: TOTAL
A4: TOTAL POR ESPECIALIDADE | D4: =COUNTIFS('Casuística'!$H$3:$H$302,"=Cirurgia Geral") | E4: =COUNTIFS('Casuística'!$H$3:$H$302,"=Cirurgia Pediátrica") | F4: =COUNTIFS('Casuística'!$H$3:$H$302,"=Cirurgia Plástica") | G4: =COUNTIFS('Casuística'!$H$3:$H$302,"=Cirurgia Vascular") | H4: =COUNTIFS('Casuística'!$H$3:$H$302,"=Ginecologia/Obstetrícia") | I4: =COUNTIFS('Casuística'!$H$3:$H$302,"=Neurocirurgia") | J4: =COUNTIFS('Casuística'!$H$3:$H$302,"=Oftalmologia") | K4: =COUNTIFS('Casuística'!$H$3:$H$302,"=ORL") | L4: =COUNTIFS('Casuística'!$H$3:$H$302,"=Ortopedia") | M4: =COUNTIFS('Casuística'!$H$3:$H$302,"=Urologia") | N4: =COUNTIFS('Casuística'!$H$3:$H$302,"=Fora do Bloco") | O4: =SUM(D4:N4)
A5: REGIME | B5: Urgência | D5: =COUNTIFS('Casuística'!$H$3:$H$302,"=Cirurgia Geral",'Casuística'!$G$3:$G$302,"=Urgência") | E5: =COUNTIFS('Casuística'!$H$3:$H$302,"=Cirurgia Pediátrica",'Casuística'!$G$3:$G$302,"=Urgência") | F5: =COUNTIFS('Casuística'!$H$3:$H$302,"=Cirurgia Plástica",'Casuística'!$G$3:$G$302,"=Urgência") | G5: =COUNTIFS('Casuística'!$H$3:$H$302,"=Cirurgia Vascular",'Casuística'!$G$3:$G$302,"=Urgência") | H5: =COUNTIFS('Casuística'!$H$3:$H$302,"=Ginecologia/Obstetrícia",'Casuística'!$G$3:$G$302,"=Urgência") | I5: =COUNTIFS('Casuística'!$H$3:$H$302,"=Neurocirurgia",'Casuística'!$G$3:$G$302,"=Urgência") | J5: =COUNTIFS('Casuística'!$H$3:$H$302,"=Oftalmologia",'Casuística'!$G$3:$G$302,"=Urgência") | K5: =COUNTIFS('Casuística'!$H$3:$H$302,"=ORL",'Casuística'!$G$3:$G$302,"=Urgência") | L5: =COUNTIFS('Casuística'!$H$3:$H$302,"=Ortopedia",'Casuística'!$G$3:$G$302,"=Urgência") | M5: =COUNTIFS('Casuística'!$H$3:$H$302,"=Urologia",'Casuística'!$G$3:$G$302,"=Urgência") | N5: =COUNTIFS('Casuística'!$H$3:$H$302,"=Fora do Bloco",'Casuística'!$G$3:$G$302,"=Urgência") | O5: =SUM(D5:N5)
B6: Internamento (programada) | D6: =COUNTIFS('Casuística'!$H$3:$H$302,"=Cirurgia Geral",'Casuística'!$G$3:$G$302,"=Internamento (programada)") | E6: =COUNTIFS('Casuística'!$H$3:$H$302,"=Cirurgia Pediátrica",'Casuística'!$G$3:$G$302,"=Internamento (programada)") | F6: =COUNTIFS('Casuística'!$H$3:$H$302,"=Cirurgia Plástica",'Casuística'!$G$3:$G$302,"=Internamento (programada)") | G6: =COUNTIFS('Casuística'!$H$3:$H$302,"=Cirurgia Vascular",'Casuística'!$G$3:$G$302,"=Internamento (programada)") | H6: =COUNTIFS('Casuística'!$H$3:$H$302,"=Ginecologia/Obstetrícia",'Casuística'!$G$3:$G$302,"=Internamento (programada)") | I6: =COUNTIFS('Casuística'!$H$3:$H$302,"=Neurocirurgia",'Casuística'!$G$3:$G$302,"=Internamento (programada)") | J6: =COUNTIFS('Casuística'!$H$3:$H$302,"=Oftalmologia",'Casuística'!$G$3:$G$302,"=Internamento (programada)") | K6: =COUNTIFS('Casuística'!$H$3:$H$302,"=ORL",'Casuística'!$G$3:$G$302,"=Internamento (programada)") | L6: =COUNTIFS('Casuística'!$H$3:$H$302,"=Ortopedia",'Casuística'!$G$3:$G$302,"=Internamento (programada)") | M6: =COUNTIFS('Casuística'!$H$3:$H$302,"=Urologia",'Casuística'!$G$3:$G$302,"=Internamento (programada)") | N6: =COUNTIFS('Casuística'!$H$3:$H$302,"=Fora do Bloco",'Casuística'!$G$3:$G$302,"=Internamento (programada)") | O6: =SUM(D6:N6)
B7: Ambulatório (programada) | D7: =COUNTIFS('Casuística'!$H$3:$H$302,"=Cirurgia Geral",'Casuística'!$G$3:$G$302,"=Ambulatório (programada)") | E7: =COUNTIFS('Casuística'!$H$3:$H$302,"=Cirurgia Pediátrica",'Casuística'!$G$3:$G$302,"=Ambulatório (programada)") | F7: =COUNTIFS('Casuística'!$H$3:$H$302,"=Cirurgia Plástica",'Casuística'!$G$3:$G$302,"=Ambulatório (programada)") | G7: =COUNTIFS('Casuística'!$H$3:$H$302,"=Cirurgia Vascular",'Casuística'!$G$3:$G$302,"=Ambulatório (programada)") | H7: =COUNTIFS('Casuística'!$H$3:$H$302,"=Ginecologia/Obstetrícia",'Casuística'!$G$3:$G$302,"=Ambulatório (programada)") | I7: =COUNTIFS('Casuística'!$H$3:$H$302,"=Neurocirurgia",'Casuística'!$G$3:$G$302,"=Ambulatório (programada)") | J7: =COUNTIFS('Casuística'!$H$3:$H$302,"=Oftalmologia",'Casuística'!$G$3:$G$302,"=Ambulatório (programada)") | K7: =COUNTIFS('Casuística'!$H$3:$H$302,"=ORL",'Casuística'!$G$3:$G$302,"=Ambulatório (programada)") | L7: =COUNTIFS('Casuística'!$H$3:$H$302,"=Ortopedia",'Casuística'!$G$3:$G$302,"=Ambulatório (programada)") | M7: =COUNTIFS('Casuística'!$H$3:$H$302,"=Urologia",'Casuística'!$G$3:$G$302,"=Ambulatório (programada)") | N7: =COUNTIFS('Casuística'!$H$3:$H$302,"=Fora do Bloco",'Casuística'!$G$3:$G$302,"=Ambulatório (programada)") | O7: =SUM(D7:N7)
A8: SEXO | B8: Feminino | D8: =COUNTIFS('Casuística'!$H$3:$H$302,"=Cirurgia Geral",'Casuística'!$E$3:$E$302,"=Feminino") | E8: =COUNTIFS('Casuística'!$H$3:$H$302,"=Cirurgia Pediátrica",'Casuística'!$E$3:$E$302,"=Feminino") | F8: =COUNTIFS('Casuística'!$H$3:$H$302,"=Cirurgia Plástica",'Casuística'!$E$3:$E$302,"=Feminino") | G8: =COUNTIFS('Casuística'!$H$3:$H$302,"=Cirurgia Vascular",'Casuística'!$E$3:$E$302,"=Feminino") | H8: =COUNTIFS('Casuística'!$H$3:$H$302,"=Ginecologia/Obstetrícia",'Casuística'!$E$3:$E$302,"=Feminino") | I8: =COUNTIFS('Casuística'!$H$3:$H$302,"=Neurocirurgia",'Casuística'!$E$3:$E$302,"=Feminino") | J8: =COUNTIFS('Casuística'!$H$3:$H$302,"=Oftalmologia",'Casuística'!$E$3:$E$302,"=Feminino") | K8: =COUNTIFS('Casuística'!$H$3:$H$302,"=ORL",'Casuística'!$E$3:$E$302,"=Feminino") | L8: =COUNTIFS('Casuística'!$H$3:$H$302,"=Ortopedia",'Casuística'!$E$3:$E$302,"=Feminino") | M8: =COUNTIFS('Casuística'!$H$3:$H$302,"=Urologia",'Casuística'!$E$3:$E$302,"=Feminino") | N8: =COUNTIFS('Casuística'!$H$3:$H$302,"=Fora do Bloco",'Casuística'!$E$3:$E$302,"=Feminino") | O8: =SUM(D8:N8)
B9: Masculino | D9: =COUNTIFS('Casuística'!$H$3:$H$302,"=Cirurgia Geral",'Casuística'!$E$3:$E$302,"=Masculino") | E9: =COUNTIFS('Casuística'!$H$3:$H$302,"=Cirurgia Pediátrica",'Casuística'!$E$3:$E$302,"=Masculino") | F9: =COUNTIFS('Casuística'!$H$3:$H$302,"=Cirurgia Plástica",'Casuística'!$E$3:$E$302,"=Masculino") | G9: =COUNTIFS('Casuística'!$H$3:$H$302,"=Cirurgia Vascular",'Casuística'!$E$3:$E$302,"=Masculino") | H9: =COUNTIFS('Casuística'!$H$3:$H$302,"=Ginecologia/Obstetrícia",'Casuística'!$E$3:$E$302,"=Masculino") | I9: =COUNTIFS('Casuística'!$H$3:$H$302,"=Neurocirurgia",'Casuística'!$E$3:$E$302,"=Masculino") | J9: =COUNTIFS('Casuística'!$H$3:$H$302,"=Oftalmologia",'Casuística'!$E$3:$E$302,"=Masculino") | K9: =COUNTIFS('Casuística'!$H$3:$H$302,"=ORL",'Casuística'!$E$3:$E$302,"=Masculino") | L9: =COUNTIFS('Casuística'!$H$3:$H$302,"=Ortopedia",'Casuística'!$E$3:$E$302,"=Masculino") | M9: =COUNTIFS('Casuística'!$H$3:$H$302,"=Urologia",'Casuística'!$E$3:$E$302,"=Masculino") | N9: =COUNTIFS('Casuística'!$H$3:$H$302,"=Fora do Bloco",'Casuística'!$E$3:$E$302,"=Masculino") | O9: =SUM(D9:N9)
A10: FAIXA ETÁRIA | B10: < 24 horas | D10: =COUNTIFS('Casuística'!$H$3:$H$302,"=Cirurgia Geral",'Casuística'!$D$3:$D$302,"=< 24 horas") | E10: =COUNTIFS('Casuística'!$H$3:$H$302,"=Cirurgia Pediátrica",'Casuística'!$D$3:$D$302,"=< 24 horas") | F10: =COUNTIFS('Casuística'!$H$3:$H$302,"=Cirurgia Plástica",'Casuística'!$D$3:$D$302,"=< 24 horas") | G10: =COUNTIFS('Casuística'!$H$3:$H$302,"=Cirurgia Vascular",'Casuística'!$D$3:$D$302,"=< 24 horas") | H10: =COUNTIFS('Casuística'!$H$3:$H$302,"=Ginecologia/Obstetrícia",'Casuística'!$D$3:$D$302,"=< 24 horas") | I10: =COUNTIFS('Casuística'!$H$3:$H$302,"=Neurocirurgia",'Casuística'!$D$3:$D$302,"=< 24 horas") | J10: =COUNTIFS('Casuística'!$H$3:$H$302,"=Oftalmologia",'Casuística'!$D$3:$D$302,"=< 24 horas") | K10: =COUNTIFS('Casuística'!$H$3:$H$302,"=ORL",'Casuística'!$D$3:$D$302,"=< 24 horas") | L10: =COUNTIFS('Casuística'!$H$3:$H$302,"=Ortopedia",'Casuística'!$D$3:$D$302,"=< 24 horas") | M10: =COUNTIFS('Casuística'!$H$3:$H$302,"=Urologia",'Casuística'!$D$3:$D$302,"=< 24 horas") | N10: =COUNTIFS('Casuística'!$H$3:$H$302,"=Fora do Bloco",'Casuística'!$D$3:$D$302,"=< 24 horas") | O10: =SUM(D10:N10)
B11: 24 horas a 1 mês | D11: =COUNTIFS('Casuística'!$H$3:$H$302,"=Cirurgia Geral",'Casuística'!$D$3:$D$302,"=24 horas a 1 mês") | E11: =COUNTIFS('Casuística'!$H$3:$H$302,"=Cirurgia Pediátrica",'Casuística'!$D$3:$D$302,"=24 horas a 1 mês") | F11: =COUNTIFS('Casuística'!$H$3:$H$302,"=Cirurgia Plástica",'Casuística'!$D$3:$D$302,"=24 horas a 1 mês") | G11: =COUNTIFS('Casuística'!$H$3:$H$302,"=Cirurgia Vascular",'Casuística'!$D$3:$D$302,"=24 horas a 1 mês") | H11: =COUNTIFS('Casuística'!$H$3:$H$302,"=Ginecologia/Obstetrícia",'Casuística'!$D$3:$D$302,"=24 horas a 1 mês") | I11: =COUNTIFS('Casuística'!$H$3:$H$302,"=Neurocirurgia",'Casuística'!$D$3:$D$302,"=24 horas a 1 mês") | J11: =COUNTIFS('Casuística'!$H$3:$H$302,"=Oftalmologia",'Casuística'!$D$3:$D$302,"=24 horas a 1 mês") | K11: =COUNTIFS('Casuística'!$H$3:$H$302,"=ORL",'Casuística'!$D$3:$D$302,"=24 horas a 1 mês") | L11: =COUNTIFS('Casuística'!$H$3:$H$302,"=Ortopedia",'Casuística'!$D$3:$D$302,"=24 horas a 1 mês") | M11: =COUNTIFS('Casuística'!$H$3:$H$302,"=Urologia",'Casuística'!$D$3:$D$302,"=24 horas a 1 mês") | N11: =COUNTIFS('Casuística'!$H$3:$H$302,"=Fora do Bloco",'Casuística'!$D$3:$D$302,"=24 horas a 1 mês") | O11: =SUM(D11:N11)
B12: > 1 mês a 6 meses | D12: =COUNTIFS('Casuística'!$H$3:$H$302,"=Cirurgia Geral",'Casuística'!$D$3:$D$302,"=> 1 mês a 6 meses") | E12: =COUNTIFS('Casuística'!$H$3:$H$302,"=Cirurgia Pediátrica",'Casuística'!$D$3:$D$302,"=> 1 mês a 6 meses") | F12: =COUNTIFS('Casuística'!$H$3:$H$302,"=Cirurgia Plástica",'Casuística'!$D$3:$D$302,"=> 1 mês a 6 meses") | G12: =COUNTIFS('Casuística'!$H$3:$H$302,"=Cirurgia Vascular",'Casuística'!$D$3:$D$302,"=> 1 mês a 6 meses") | H12: =COUNTIFS('Casuística'!$H$3:$H$302,"=Ginecologia/Obstetrícia",'Casuística'!$D$3:$D$302,"=> 1 mês a 6 meses") | I12: =COUNTIFS('Casuística'!$H$3:$H$302,"=Neurocirurgia",'Casuística'!$D$3:$D$302,"=> 1 mês a 6 meses") | J12: =COUNTIFS('Casuística'!$H$3:$H$302,"=Oftalmologia",'Casuística'!$D$3:$D$302,"=> 1 mês a 6 meses") | K12: =COUNTIFS('Casuística'!$H$3:$H$302,"=ORL",'Casuística'!$D$3:$D$302,"=> 1 mês a 6 meses") | L12: =COUNTIFS('Casuística'!$H$3:$H$302,"=Ortopedia",'Casuística'!$D$3:$D$302,"=> 1 mês a 6 meses") | M12: =COUNTIFS('Casuística'!$H$3:$H$302,"=Urologia",'Casuística'!$D$3:$D$302,"=> 1 mês a 6 meses") | N12: =COUNTIFS('Casuística'!$H$3:$H$302,"=Fora do Bloco",'Casuística'!$D$3:$D$302,"=> 1 mês a 6 meses") | O12: =SUM(D12:N12)
B13: > 6 meses a 4 anos | D13: =COUNTIFS('Casuística'!$H$3:$H$302,"=Cirurgia Geral",'Casuística'!$D$3:$D$302,"=> 6 meses a 4 anos") | E13: =COUNTIFS('Casuística'!$H$3:$H$302,"=Cirurgia Pediátrica",'Casuística'!$D$3:$D$302,"=> 6 meses a 4 anos") | F13: =COUNTIFS('Casuística'!$H$3:$H$302,"=Cirurgia Plástica",'Casuística'!$D$3:$D$302,"=> 6 meses a 4 anos") | G13: =COUNTIFS('Casuística'!$H$3:$H$302,"=Cirurgia Vascular",'Casuística'!$D$3:$D$302,"=> 6 meses a 4 anos") | H13: =COUNTIFS('Casuística'!$H$3:$H$302,"=Ginecologia/Obstetrícia",'Casuística'!$D$3:$D$302,"=> 6 meses a 4 anos") | I13: =COUNTIFS('Casuística'!$H$3:$H$302,"=Neurocirurgia",'Casuística'!$D$3:$D$302,"=> 6 meses a 4 anos") | J13: =COUNTIFS('Casuística'!$H$3:$H$302,"=Oftalmologia",'Casuística'!$D$3:$D$302,"=> 6 meses a 4 anos") | K13: =COUNTIFS('Casuística'!$H$3:$H$302,"=ORL",'Casuística'!$D$3:$D$302,"=> 6 meses a 4 anos") | L13: =COUNTIFS('Casuística'!$H$3:$H$302,"=Ortopedia",'Casuística'!$D$3:$D$302,"=> 6 meses a 4 anos") | M13: =COUNTIFS('Casuística'!$H$3:$H$302,"=Urologia",'Casuística'!$D$3:$D$302,"=> 6 meses a 4 anos") | N13: =COUNTIFS('Casuística'!$H$3:$H$302,"=Fora do Bloco",'Casuística'!$D$3:$D$302,"=> 6 meses a 4 anos") | O13: =SUM(D13:N13)
B14: > 4 anos a 12 anos | D14: =COUNTIFS('Casuística'!$H$3:$H$302,"=Cirurgia Geral",'Casuística'!$D$3:$D$302,"=> 4 anos a 12 anos") | E14: =COUNTIFS('Casuística'!$H$3:$H$302,"=Cirurgia Pediátrica",'Casuística'!$D$3:$D$302,"=> 4 anos a 12 anos") | F14: =COUNTIFS('Casuística'!$H$3:$H$302,"=Cirurgia Plástica",'Casuística'!$D$3:$D$302,"=> 4 anos a 12 anos") | G14: =COUNTIFS('Casuística'!$H$3:$H$302,"=Cirurgia Vascular",'Casuística'!$D$3:$D$302,"=> 4 anos a 12 anos") | H14: =COUNTIFS('Casuística'!$H$3:$H$302,"=Ginecologia/Obstetrícia",'Casuística'!$D$3:$D$302,"=> 4 anos a 12 anos") | I14: =COUNTIFS('Casuística'!$H$3:$H$302,"=Neurocirurgia",'Casuística'!$D$3:$D$302,"=> 4 anos a 12 anos") | J14: =COUNTIFS('Casuística'!$H$3:$H$302,"=Oftalmologia",'Casuística'!$D$3:$D$302,"=> 4 anos a 12 anos") | K14: =COUNTIFS('Casuística'!$H$3:$H$302,"=ORL",'Casuística'!$D$3:$D$302,"=> 4 anos a 12 anos") | L14: =COUNTIFS('Casuística'!$H$3:$H$302,"=Ortopedia",'Casuística'!$D$3:$D$302,"=> 4 anos a 12 anos") | M14: =COUNTIFS('Casuística'!$H$3:$H$302,"=Urologia",'Casuística'!$D$3:$D$302,"=> 4 anos a 12 anos") | N14: =COUNTIFS('Casuística'!$H$3:$H$302,"=Fora do Bloco",'Casuística'!$D$3:$D$302,"=> 4 anos a 12 anos") | O14: =SUM(D14:N14)
B15: > 12 anos a 65 anos | D15: =COUNTIFS('Casuística'!$H$3:$H$302,"=Cirurgia Geral",'Casuística'!$D$3:$D$302,"=> 12 anos a 65 anos") | E15: =COUNTIFS('Casuística'!$H$3:$H$302,"=Cirurgia Pediátrica",'Casuística'!$D$3:$D$302,"=> 12 anos a 65 anos") | F15: =COUNTIFS('Casuística'!$H$3:$H$302,"=Cirurgia Plástica",'Casuística'!$D$3:$D$302,"=> 12 anos a 65 anos") | G15: =COUNTIFS('Casuística'!$H$3:$H$302,"=Cirurgia Vascular",'Casuística'!$D$3:$D$302,"=> 12 anos a 65 anos") | H15: =COUNTIFS('Casuística'!$H$3:$H$302,"=Ginecologia/Obstetrícia",'Casuística'!$D$3:$D$302,"=> 12 anos a 65 anos") | I15: =COUNTIFS('Casuística'!$H$3:$H$302,"=Neurocirurgia",'Casuística'!$D$3:$D$302,"=> 12 anos a 65 anos") | J15: =COUNTIFS('Casuística'!$H$3:$H$302,"=Oftalmologia",'Casuística'!$D$3:$D$302,"=> 12 anos a 65 anos") | K15: =COUNTIFS('Casuística'!$H$3:$H$302,"=ORL",'Casuística'!$D$3:$D$302,"=> 12 anos a 65 anos") | L15: =COUNTIFS('Casuística'!$H$3:$H$302,"=Ortopedia",'Casuística'!$D$3:$D$302,"=> 12 anos a 65 anos") | M15: =COUNTIFS('Casuística'!$H$3:$H$302,"=Urologia",'Casuística'!$D$3:$D$302,"=> 12 anos a 65 anos") | N15: =COUNTIFS('Casuística'!$H$3:$H$302,"=Fora do Bloco",'Casuística'!$D$3:$D$302,"=> 12 anos a 65 anos") | O15: =SUM(D15:N15)
B16: > 65 anos a 85 anos | D16: =COUNTIFS('Casuística'!$H$3:$H$302,"=Cirurgia Geral",'Casuística'!$D$3:$D$302,"=> 65 anos a 85 anos") | E16: =COUNTIFS('Casuística'!$H$3:$H$302,"=Cirurgia Pediátrica",'Casuística'!$D$3:$D$302,"=> 65 anos a 85 anos") | F16: =COUNTIFS('Casuística'!$H$3:$H$302,"=Cirurgia Plástica",'Casuística'!$D$3:$D$302,"=> 65 anos a 85 anos") | G16: =COUNTIFS('Casuística'!$H$3:$H$302,"=Cirurgia Vascular",'Casuística'!$D$3:$D$302,"=> 65 anos a 85 anos") | H16: =COUNTIFS('Casuística'!$H$3:$H$302,"=Ginecologia/Obstetrícia",'Casuística'!$D$3:$D$302,"=> 65 anos a 85 anos") | I16: =COUNTIFS('Casuística'!$H$3:$H$302,"=Neurocirurgia",'Casuística'!$D$3:$D$302,"=> 65 anos a 85 anos") | J16: =COUNTIFS('Casuística'!$H$3:$H$302,"=Oftalmologia",'Casuística'!$D$3:$D$302,"=> 65 anos a 85 anos") | K16: =COUNTIFS('Casuística'!$H$3:$H$302,"=ORL",'Casuística'!$D$3:$D$302,"=> 65 anos a 85 anos") | L16: =COUNTIFS('Casuística'!$H$3:$H$302,"=Ortopedia",'Casuística'!$D$3:$D$302,"=> 65 anos a 85 anos") | M16: =COUNTIFS('Casuística'!$H$3:$H$302,"=Urologia",'Casuística'!$D$3:$D$302,"=> 65 anos a 85 anos") | N16: =COUNTIFS('Casuística'!$H$3:$H$302,"=Fora do Bloco",'Casuística'!$D$3:$D$302,"=> 65 anos a 85 anos") | O16: =SUM(D16:N16)
B17: > 85 anos | D17: =COUNTIFS('Casuística'!$H$3:$H$302,"=Cirurgia Geral",'Casuística'!$D$3:$D$302,"=> 85 anos") | E17: =COUNTIFS('Casuística'!$H$3:$H$302,"=Cirurgia Pediátrica",'Casuística'!$D$3:$D$302,"=> 85 anos") | F17: =COUNTIFS('Casuística'!$H$3:$H$302,"=Cirurgia Plástica",'Casuística'!$D$3:$D$302,"=> 85 anos") | G17: =COUNTIFS('Casuística'!$H$3:$H$302,"=Cirurgia Vascular",'Casuística'!$D$3:$D$302,"=> 85 anos") | H17: =COUNTIFS('Casuística'!$H$3:$H$302,"=Ginecologia/Obstetrícia",'Casuística'!$D$3:$D$302,"=> 85 anos") | I17: =COUNTIFS('Casuística'!$H$3:$H$302,"=Neurocirurgia",'Casuística'!$D$3:$D$302,"=> 85 anos") | J17: =COUNTIFS('Casuística'!$H$3:$H$302,"=Oftalmologia",'Casuística'!$D$3:$D$302,"=> 85 anos") | K17: =COUNTIFS('Casuística'!$H$3:$H$302,"=ORL",'Casuística'!$D$3:$D$302,"=> 85 anos") | L17: =COUNTIFS('Casuística'!$H$3:$H$302,"=Ortopedia",'Casuística'!$D$3:$D$302,"=> 85 anos") | M17: =COUNTIFS('Casuística'!$H$3:$H$302,"=Urologia",'Casuística'!$D$3:$D$302,"=> 85 anos") | N17: =COUNTIFS('Casuística'!$H$3:$H$302,"=Fora do Bloco",'Casuística'!$D$3:$D$302,"=> 85 anos") | O17: =SUM(D17:N17)
A18: ESTADO FÍSICO | B18: ASA I | D18: =COUNTIFS('Casuística'!$H$3:$H$302,"=Cirurgia Geral",'Casuística'!$F$3:$F$302,"=I") | E18: =COUNTIFS('Casuística'!$H$3:$H$302,"=Cirurgia Pediátrica",'Casuística'!$F$3:$F$302,"=I") | F18: =COUNTIFS('Casuística'!$H$3:$H$302,"=Cirurgia Plástica",'Casuística'!$F$3:$F$302,"=I") | G18: =COUNTIFS('Casuística'!$H$3:$H$302,"=Cirurgia Vascular",'Casuística'!$F$3:$F$302,"=I") | H18: =COUNTIFS('Casuística'!$H$3:$H$302,"=Ginecologia/Obstetrícia",'Casuística'!$F$3:$F$302,"=I") | I18: =COUNTIFS('Casuística'!$H$3:$H$302,"=Neurocirurgia",'Casuística'!$F$3:$F$302,"=I") | J18: =COUNTIFS('Casuística'!$H$3:$H$302,"=Oftalmologia",'Casuística'!$F$3:$F$302,"=I") | K18: =COUNTIFS('Casuística'!$H$3:$H$302,"=ORL",'Casuística'!$F$3:$F$302,"=I") | L18: =COUNTIFS('Casuística'!$H$3:$H$302,"=Ortopedia",'Casuística'!$F$3:$F$302,"=I") | M18: =COUNTIFS('Casuística'!$H$3:$H$302,"=Urologia",'Casuística'!$F$3:$F$302,"=I") | N18: =COUNTIFS('Casuística'!$H$3:$H$302,"=Fora do Bloco",'Casuística'!$F$3:$F$302,"=I") | O18: =SUM(D18:N18)
B19: ASA II | D19: =COUNTIFS('Casuística'!$H$3:$H$302,"=Cirurgia Geral",'Casuística'!$F$3:$F$302,"=II") | E19: =COUNTIFS('Casuística'!$H$3:$H$302,"=Cirurgia Pediátrica",'Casuística'!$F$3:$F$302,"=II") | F19: =COUNTIFS('Casuística'!$H$3:$H$302,"=Cirurgia Plástica",'Casuística'!$F$3:$F$302,"=II") | G19: =COUNTIFS('Casuística'!$H$3:$H$302,"=Cirurgia Vascular",'Casuística'!$F$3:$F$302,"=II") | H19: =COUNTIFS('Casuística'!$H$3:$H$302,"=Ginecologia/Obstetrícia",'Casuística'!$F$3:$F$302,"=II") | I19: =COUNTIFS('Casuística'!$H$3:$H$302,"=Neurocirurgia",'Casuística'!$F$3:$F$302,"=II") | J19: =COUNTIFS('Casuística'!$H$3:$H$302,"=Oftalmologia",'Casuística'!$F$3:$F$302,"=II") | K19: =COUNTIFS('Casuística'!$H$3:$H$302,"=ORL",'Casuística'!$F$3:$F$302,"=II") | L19: =COUNTIFS('Casuística'!$H$3:$H$302,"=Ortopedia",'Casuística'!$F$3:$F$302,"=II") | M19: =COUNTIFS('Casuística'!$H$3:$H$302,"=Urologia",'Casuística'!$F$3:$F$302,"=II") | N19: =COUNTIFS('Casuística'!$H$3:$H$302,"=Fora do Bloco",'Casuística'!$F$3:$F$302,"=II") | O19: =SUM(D19:N19)
B20: ASA III | D20: =COUNTIFS('Casuística'!$H$3:$H$302,"=Cirurgia Geral",'Casuística'!$F$3:$F$302,"=III") | E20: =COUNTIFS('Casuística'!$H$3:$H$302,"=Cirurgia Pediátrica",'Casuística'!$F$3:$F$302,"=III") | F20: =COUNTIFS('Casuística'!$H$3:$H$302,"=Cirurgia Plástica",'Casuística'!$F$3:$F$302,"=III") | G20: =COUNTIFS('Casuística'!$H$3:$H$302,"=Cirurgia Vascular",'Casuística'!$F$3:$F$302,"=III") | H20: =COUNTIFS('Casuística'!$H$3:$H$302,"=Ginecologia/Obstetrícia",'Casuística'!$F$3:$F$302,"=III") | I20: =COUNTIFS('Casuística'!$H$3:$H$302,"=Neurocirurgia",'Casuística'!$F$3:$F$302,"=III") | J20: =COUNTIFS('Casuística'!$H$3:$H$302,"=Oftalmologia",'Casuística'!$F$3:$F$302,"=III") | K20: =COUNTIFS('Casuística'!$H$3:$H$302,"=ORL",'Casuística'!$F$3:$F$302,"=III") | L20: =COUNTIFS('Casuística'!$H$3:$H$302,"=Ortopedia",'Casuística'!$F$3:$F$302,"=III") | M20: =COUNTIFS('Casuística'!$H$3:$H$302,"=Urologia",'Casuística'!$F$3:$F$302,"=III") | N20: =COUNTIFS('Casuística'!$H$3:$H$302,"=Fora do Bloco",'Casuística'!$F$3:$F$302,"=III") | O20: =SUM(D20:N20)
B21: ASA IV | D21: =COUNTIFS('Casuística'!$H$3:$H$302,"=Cirurgia Geral",'Casuística'!$F$3:$F$302,"=IV") | E21: =COUNTIFS('Casuística'!$H$3:$H$302,"=Cirurgia Pediátrica",'Casuística'!$F$3:$F$302,"=IV") | F21: =COUNTIFS('Casuística'!$H$3:$H$302,"=Cirurgia Plástica",'Casuística'!$F$3:$F$302,"=IV") | G21: =COUNTIFS('Casuística'!$H$3:$H$302,"=Cirurgia Vascular",'Casuística'!$F$3:$F$302,"=IV") | H21: =COUNTIFS('Casuística'!$H$3:$H$302,"=Ginecologia/Obstetrícia",'Casuística'!$F$3:$F$302,"=IV") | I21: =COUNTIFS('Casuística'!$H$3:$H$302,"=Neurocirurgia",'Casuística'!$F$3:$F$302,"=IV") | J21: =COUNTIFS('Casuística'!$H$3:$H$302,"=Oftalmologia",'Casuística'!$F$3:$F$302,"=IV") | K21: =COUNTIFS('Casuística'!$H$3:$H$302,"=ORL",'Casuística'!$F$3:$F$302,"=IV") | L21: =COUNTIFS('Casuística'!$H$3:$H$302,"=Ortopedia",'Casuística'!$F$3:$F$302,"=IV") | M21: =COUNTIFS('Casuística'!$H$3:$H$302,"=Urologia",'Casuística'!$F$3:$F$302,"=IV") | N21: =COUNTIFS('Casuística'!$H$3:$H$302,"=Fora do Bloco",'Casuística'!$F$3:$F$302,"=IV") | O21: =SUM(D21:N21)
B22: ASA V | D22: =COUNTIFS('Casuística'!$H$3:$H$302,"=Cirurgia Geral",'Casuística'!$F$3:$F$302,"=V") | E22: =COUNTIFS('Casuística'!$H$3:$H$302,"=Cirurgia Pediátrica",'Casuística'!$F$3:$F$302,"=V") | F22: =COUNTIFS('Casuística'!$H$3:$H$302,"=Cirurgia Plástica",'Casuística'!$F$3:$F$302,"=V") | G22: =COUNTIFS('Casuística'!$H$3:$H$302,"=Cirurgia Vascular",'Casuística'!$F$3:$F$302,"=V") | H22: =COUNTIFS('Casuística'!$H$3:$H$302,"=Ginecologia/Obstetrícia",'Casuística'!$F$3:$F$302,"=V") | I22: =COUNTIFS('Casuística'!$H$3:$H$302,"=Neurocirurgia",'Casuística'!$F$3:$F$302,"=V") | J22: =COUNTIFS('Casuística'!$H$3:$H$302,"=Oftalmologia",'Casuística'!$F$3:$F$302,"=V") | K22: =COUNTIFS('Casuística'!$H$3:$H$302,"=ORL",'Casuística'!$F$3:$F$302,"=V") | L22: =COUNTIFS('Casuística'!$H$3:$H$302,"=Ortopedia",'Casuística'!$F$3:$F$302,"=V") | M22: =COUNTIFS('Casuística'!$H$3:$H$302,"=Urologia",'Casuística'!$F$3:$F$302,"=V") | N22: =COUNTIFS('Casuística'!$H$3:$H$302,"=Fora do Bloco",'Casuística'!$F$3:$F$302,"=V") | O22: =SUM(D22:N22)
A23: TÉCNICA ANESTÉSICA | B23: Anestesia Geral | C23: Endovenosa | D23: =COUNTIFS('Casuística'!$H$3:$H$302,"=Cirurgia Geral",'Casuística'!$N$3:$N$302,"=Geral",'Casuística'!$O$3:$O$302,"=Endovenosa") | E23: =COUNTIFS('Casuística'!$H$3:$H$302,"=Cirurgia Pediátrica",'Casuística'!$N$3:$N$302,"=Geral",'Casuística'!$O$3:$O$302,"=Endovenosa") | F23: =COUNTIFS('Casuística'!$H$3:$H$302,"=Cirurgia Plástica",'Casuística'!$N$3:$N$302,"=Geral",'Casuística'!$O$3:$O$302,"=Endovenosa") | G23: =COUNTIFS('Casuística'!$H$3:$H$302,"=Cirurgia Vascular",'Casuística'!$N$3:$N$302,"=Geral",'Casuística'!$O$3:$O$302,"=Endovenosa") | H23: =COUNTIFS('Casuística'!$H$3:$H$302,"=Ginecologia/Obstetrícia",'Casuística'!$N$3:$N$302,"=Geral",'Casuística'!$O$3:$O$302,"=Endovenosa") | I23: =COUNTIFS('Casuística'!$H$3:$H$302,"=Neurocirurgia",'Casuística'!$N$3:$N$302,"=Geral",'Casuística'!$O$3:$O$302,"=Endovenosa") | J23: =COUNTIFS('Casuística'!$H$3:$H$302,"=Oftalmologia",'Casuística'!$N$3:$N$302,"=Geral",'Casuística'!$O$3:$O$302,"=Endovenosa") | K23: =COUNTIFS('Casuística'!$H$3:$H$302,"=ORL",'Casuística'!$N$3:$N$302,"=Geral",'Casuística'!$O$3:$O$302,"=Endovenosa") | L23: =COUNTIFS('Casuística'!$H$3:$H$302,"=Ortopedia",'Casuística'!$N$3:$N$302,"=Geral",'Casuística'!$O$3:$O$302,"=Endovenosa") | M23: =COUNTIFS('Casuística'!$H$3:$H$302,"=Urologia",'Casuística'!$N$3:$N$302,"=Geral",'Casuística'!$O$3:$O$302,"=Endovenosa") | N23: =COUNTIFS('Casuística'!$H$3:$H$302,"=Fora do Bloco",'Casuística'!$N$3:$N$302,"=Geral",'Casuística'!$O$3:$O$302,"=Endovenosa") | O23: =SUM(D23:N23)
C24: Balanceada | D24: =COUNTIFS('Casuística'!$H$3:$H$302,"=Cirurgia Geral",'Casuística'!$N$3:$N$302,"=Geral",'Casuística'!$O$3:$O$302,"=Balanceada") | E24: =COUNTIFS('Casuística'!$H$3:$H$302,"=Cirurgia Pediátrica",'Casuística'!$N$3:$N$302,"=Geral",'Casuística'!$O$3:$O$302,"=Balanceada") | F24: =COUNTIFS('Casuística'!$H$3:$H$302,"=Cirurgia Plástica",'Casuística'!$N$3:$N$302,"=Geral",'Casuística'!$O$3:$O$302,"=Balanceada") | G24: =COUNTIFS('Casuística'!$H$3:$H$302,"=Cirurgia Vascular",'Casuística'!$N$3:$N$302,"=Geral",'Casuística'!$O$3:$O$302,"=Balanceada") | H24: =COUNTIFS('Casuística'!$H$3:$H$302,"=Ginecologia/Obstetrícia",'Casuística'!$N$3:$N$302,"=Geral",'Casuística'!$O$3:$O$302,"=Balanceada") | I24: =COUNTIFS('Casuística'!$H$3:$H$302,"=Neurocirurgia",'Casuística'!$N$3:$N$302,"=Geral",'Casuística'!$O$3:$O$302,"=Balanceada") | J24: =COUNTIFS('Casuística'!$H$3:$H$302,"=Oftalmologia",'Casuística'!$N$3:$N$302,"=Geral",'Casuística'!$O$3:$O$302,"=Balanceada") | K24: =COUNTIFS('Casuística'!$H$3:$H$302,"=ORL",'Casuística'!$N$3:$N$302,"=Geral",'Casuística'!$O$3:$O$302,"=Balanceada") | L24: =COUNTIFS('Casuística'!$H$3:$H$302,"=Ortopedia",'Casuística'!$N$3:$N$302,"=Geral",'Casuística'!$O$3:$O$302,"=Balanceada") | M24: =COUNTIFS('Casuística'!$H$3:$H$302,"=Urologia",'Casuística'!$N$3:$N$302,"=Geral",'Casuística'!$O$3:$O$302,"=Balanceada") | N24: =COUNTIFS('Casuística'!$H$3:$H$302,"=Fora do Bloco",'Casuística'!$N$3:$N$302,"=Geral",'Casuística'!$O$3:$O$302,"=Balanceada") | O24: =SUM(D24:N24)
C25: Inalatória | D25: =COUNTIFS('Casuística'!$H$3:$H$302,"=Cirurgia Geral",'Casuística'!$N$3:$N$302,"=Geral",'Casuística'!$O$3:$O$302,"=Inalatória") | E25: =COUNTIFS('Casuística'!$H$3:$H$302,"=Cirurgia Pediátrica",'Casuística'!$N$3:$N$302,"=Geral",'Casuística'!$O$3:$O$302,"=Inalatória") | F25: =COUNTIFS('Casuística'!$H$3:$H$302,"=Cirurgia Plástica",'Casuística'!$N$3:$N$302,"=Geral",'Casuística'!$O$3:$O$302,"=Inalatória") | G25: =COUNTIFS('Casuística'!$H$3:$H$302,"=Cirurgia Vascular",'Casuística'!$N$3:$N$302,"=Geral",'Casuística'!$O$3:$O$302,"=Inalatória") | H25: =COUNTIFS('Casuística'!$H$3:$H$302,"=Ginecologia/Obstetrícia",'Casuística'!$N$3:$N$302,"=Geral",'Casuística'!$O$3:$O$302,"=Inalatória") | I25: =COUNTIFS('Casuística'!$H$3:$H$302,"=Neurocirurgia",'Casuística'!$N$3:$N$302,"=Geral",'Casuística'!$O$3:$O$302,"=Inalatória") | J25: =COUNTIFS('Casuística'!$H$3:$H$302,"=Oftalmologia",'Casuística'!$N$3:$N$302,"=Geral",'Casuística'!$O$3:$O$302,"=Inalatória") | K25: =COUNTIFS('Casuística'!$H$3:$H$302,"=ORL",'Casuística'!$N$3:$N$302,"=Geral",'Casuística'!$O$3:$O$302,"=Inalatória") | L25: =COUNTIFS('Casuística'!$H$3:$H$302,"=Ortopedia",'Casuística'!$N$3:$N$302,"=Geral",'Casuística'!$O$3:$O$302,"=Inalatória") | M25: =COUNTIFS('Casuística'!$H$3:$H$302,"=Urologia",'Casuística'!$N$3:$N$302,"=Geral",'Casuística'!$O$3:$O$302,"=Inalatória") | N25: =COUNTIFS('Casuística'!$H$3:$H$302,"=Fora do Bloco",'Casuística'!$N$3:$N$302,"=Geral",'Casuística'!$O$3:$O$302,"=Inalatória") | O25: =SUM(D25:N25)
B26: Anestesia Regional | C26: BSA | D26: =COUNTIFS('Casuística'!$H$3:$H$302,"=Cirurgia Geral",'Casuística'!$N$3:$N$302,"=Regional",'Casuística'!$P$3:$P$302,"=Bloqueio Subaracnoideu") | E26: =COUNTIFS('Casuística'!$H$3:$H$302,"=Cirurgia Pediátrica",'Casuística'!$N$3:$N$302,"=Regional",'Casuística'!$P$3:$P$302,"=Bloqueio Subaracnoideu") | F26: =COUNTIFS('Casuística'!$H$3:$H$302,"=Cirurgia Plástica",'Casuística'!$N$3:$N$302,"=Regional",'Casuística'!$P$3:$P$302,"=Bloqueio Subaracnoideu") | G26: =COUNTIFS('Casuística'!$H$3:$H$302,"=Cirurgia Vascular",'Casuística'!$N$3:$N$302,"=Regional",'Casuística'!$P$3:$P$302,"=Bloqueio Subaracnoideu") | H26: =COUNTIFS('Casuística'!$H$3:$H$302,"=Ginecologia/Obstetrícia",'Casuística'!$N$3:$N$302,"=Regional",'Casuística'!$P$3:$P$302,"=Bloqueio Subaracnoideu") | I26: =COUNTIFS('Casuística'!$H$3:$H$302,"=Neurocirurgia",'Casuística'!$N$3:$N$302,"=Regional",'Casuística'!$P$3:$P$302,"=Bloqueio Subaracnoideu") | J26: =COUNTIFS('Casuística'!$H$3:$H$302,"=Oftalmologia",'Casuística'!$N$3:$N$302,"=Regional",'Casuística'!$P$3:$P$302,"=Bloqueio Subaracnoideu") | K26: =COUNTIFS('Casuística'!$H$3:$H$302,"=ORL",'Casuística'!$N$3:$N$302,"=Regional",'Casuística'!$P$3:$P$302,"=Bloqueio Subaracnoideu") | L26: =COUNTIFS('Casuística'!$H$3:$H$302,"=Ortopedia",'Casuística'!$N$3:$N$302,"=Regional",'Casuística'!$P$3:$P$302,"=Bloqueio Subaracnoideu") | M26: =COUNTIFS('Casuística'!$H$3:$H$302,"=Urologia",'Casuística'!$N$3:$N$302,"=Regional",'Casuística'!$P$3:$P$302,"=Bloqueio Subaracnoideu") | N26: =COUNTIFS('Casuística'!$H$3:$H$302,"=Fora do Bloco",'Casuística'!$N$3:$N$302,"=Regional",'Casuística'!$P$3:$P$302,"=Bloqueio Subaracnoideu") | O26: =SUM(D26:N26)
C27: Epidural | D27: =COUNTIFS('Casuística'!$H$3:$H$302,"=Cirurgia Geral",'Casuística'!$N$3:$N$302,"=Regional",'Casuística'!$P$3:$P$302,"=Epidural*") | E27: =COUNTIFS('Casuística'!$H$3:$H$302,"=Cirurgia Pediátrica",'Casuística'!$N$3:$N$302,"=Regional",'Casuística'!$P$3:$P$302,"=Epidural*") | F27: =COUNTIFS('Casuística'!$H$3:$H$302,"=Cirurgia Plástica",'Casuística'!$N$3:$N$302,"=Regional",'Casuística'!$P$3:$P$302,"=Epidural*") | G27: =COUNTIFS('Casuística'!$H$3:$H$302,"=Cirurgia Vascular",'Casuística'!$N$3:$N$302,"=Regional",'Casuística'!$P$3:$P$302,"=Epidural*") | H27: =COUNTIFS('Casuística'!$H$3:$H$302,"=Ginecologia/Obstetrícia",'Casuística'!$N$3:$N$302,"=Regional",'Casuística'!$P$3:$P$302,"=Epidural*") | I27: =COUNTIFS('Casuística'!$H$3:$H$302,"=Neurocirurgia",'Casuística'!$N$3:$N$302,"=Regional",'Casuística'!$P$3:$P$302,"=Epidural*") | J27: =COUNTIFS('Casuística'!$H$3:$H$302,"=Oftalmologia",'Casuística'!$N$3:$N$302,"=Regional",'Casuística'!$P$3:$P$302,"=Epidural*") | K27: =COUNTIFS('Casuística'!$H$3:$H$302,"=ORL",'Casuística'!$N$3:$N$302,"=Regional",'Casuística'!$P$3:$P$302,"=Epidural*") | L27: =COUNTIFS('Casuística'!$H$3:$H$302,"=Ortopedia",'Casuística'!$N$3:$N$302,"=Regional",'Casuística'!$P$3:$P$302,"=Epidural*") | M27: =COUNTIFS('Casuística'!$H$3:$H$302,"=Urologia",'Casuística'!$N$3:$N$302,"=Regional",'Casuística'!$P$3:$P$302,"=Epidural*") | N27: =COUNTIFS('Casuística'!$H$3:$H$302,"=Fora do Bloco",'Casuística'!$N$3:$N$302,"=Regional",'Casuística'!$P$3:$P$302,"=Epidural*") | O27: =SUM(D27:N27)
C28: Sequencial | D28: =COUNTIFS('Casuística'!$H$3:$H$302,"=Cirurgia Geral",'Casuística'!$N$3:$N$302,"=Regional",'Casuística'!$P$3:$P$302,"=Sequencial") | E28: =COUNTIFS('Casuística'!$H$3:$H$302,"=Cirurgia Pediátrica",'Casuística'!$N$3:$N$302,"=Regional",'Casuística'!$P$3:$P$302,"=Sequencial") | F28: =COUNTIFS('Casuística'!$H$3:$H$302,"=Cirurgia Plástica",'Casuística'!$N$3:$N$302,"=Regional",'Casuística'!$P$3:$P$302,"=Sequencial") | G28: =COUNTIFS('Casuística'!$H$3:$H$302,"=Cirurgia Vascular",'Casuística'!$N$3:$N$302,"=Regional",'Casuística'!$P$3:$P$302,"=Sequencial") | H28: =COUNTIFS('Casuística'!$H$3:$H$302,"=Ginecologia/Obstetrícia",'Casuística'!$N$3:$N$302,"=Regional",'Casuística'!$P$3:$P$302,"=Sequencial") | I28: =COUNTIFS('Casuística'!$H$3:$H$302,"=Neurocirurgia",'Casuística'!$N$3:$N$302,"=Regional",'Casuística'!$P$3:$P$302,"=Sequencial") | J28: =COUNTIFS('Casuística'!$H$3:$H$302,"=Oftalmologia",'Casuística'!$N$3:$N$302,"=Regional",'Casuística'!$P$3:$P$302,"=Sequencial") | K28: =COUNTIFS('Casuística'!$H$3:$H$302,"=ORL",'Casuística'!$N$3:$N$302,"=Regional",'Casuística'!$P$3:$P$302,"=Sequencial") | L28: =COUNTIFS('Casuística'!$H$3:$H$302,"=Ortopedia",'Casuística'!$N$3:$N$302,"=Regional",'Casuística'!$P$3:$P$302,"=Sequencial") | M28: =COUNTIFS('Casuística'!$H$3:$H$302,"=Urologia",'Casuística'!$N$3:$N$302,"=Regional",'Casuística'!$P$3:$P$302,"=Sequencial") | N28: =COUNTIFS('Casuística'!$H$3:$H$302,"=Fora do Bloco",'Casuística'!$N$3:$N$302,"=Regional",'Casuística'!$P$3:$P$302,"=Sequencial") | O28: =SUM(D28:N28)
C29: BNP | D29: =COUNTIFS('Casuística'!$H$3:$H$302,"=Cirurgia Geral",'Casuística'!$N$3:$N$302,"=Regional",'Casuística'!$P$3:$P$302,"",'Casuística'!$T$3:$T$302,"<>") | E29: =COUNTIFS('Casuística'!$H$3:$H$302,"=Cirurgia Pediátrica",'Casuística'!$N$3:$N$302,"=Regional",'Casuística'!$P$3:$P$302,"",'Casuística'!$T$3:$T$302,"<>") | F29: =COUNTIFS('Casuística'!$H$3:$H$302,"=Cirurgia Plástica",'Casuística'!$N$3:$N$302,"=Regional",'Casuística'!$P$3:$P$302,"",'Casuística'!$T$3:$T$302,"<>") | G29: =COUNTIFS('Casuística'!$H$3:$H$302,"=Cirurgia Vascular",'Casuística'!$N$3:$N$302,"=Regional",'Casuística'!$P$3:$P$302,"",'Casuística'!$T$3:$T$302,"<>") | H29: =COUNTIFS('Casuística'!$H$3:$H$302,"=Ginecologia/Obstetrícia",'Casuística'!$N$3:$N$302,"=Regional",'Casuística'!$P$3:$P$302,"",'Casuística'!$T$3:$T$302,"<>") | I29: =COUNTIFS('Casuística'!$H$3:$H$302,"=Neurocirurgia",'Casuística'!$N$3:$N$302,"=Regional",'Casuística'!$P$3:$P$302,"",'Casuística'!$T$3:$T$302,"<>") | J29: =COUNTIFS('Casuística'!$H$3:$H$302,"=Oftalmologia",'Casuística'!$N$3:$N$302,"=Regional",'Casuística'!$P$3:$P$302,"",'Casuística'!$T$3:$T$302,"<>") | K29: =COUNTIFS('Casuística'!$H$3:$H$302,"=ORL",'Casuística'!$N$3:$N$302,"=Regional",'Casuística'!$P$3:$P$302,"",'Casuística'!$T$3:$T$302,"<>") | L29: =COUNTIFS('Casuística'!$H$3:$H$302,"=Ortopedia",'Casuística'!$N$3:$N$302,"=Regional",'Casuística'!$P$3:$P$302,"",'Casuística'!$T$3:$T$302,"<>") | M29: =COUNTIFS('Casuística'!$H$3:$H$302,"=Urologia",'Casuística'!$N$3:$N$302,"=Regional",'Casuística'!$P$3:$P$302,"",'Casuística'!$T$3:$T$302,"<>") | N29: =COUNTIFS('Casuística'!$H$3:$H$302,"=Fora do Bloco",'Casuística'!$N$3:$N$302,"=Regional",'Casuística'!$P$3:$P$302,"",'Casuística'!$T$3:$T$302,"<>") | O29: =SUM(D29:N29)
B30: Anestesia Combinada | D30: =COUNTIFS('Casuística'!$H$3:$H$302,"=Cirurgia Geral",'Casuística'!$N$3:$N$302,"=Combinada") | E30: =COUNTIFS('Casuística'!$H$3:$H$302,"=Cirurgia Pediátrica",'Casuística'!$N$3:$N$302,"=Combinada") | F30: =COUNTIFS('Casuística'!$H$3:$H$302,"=Cirurgia Plástica",'Casuística'!$N$3:$N$302,"=Combinada") | G30: =COUNTIFS('Casuística'!$H$3:$H$302,"=Cirurgia Vascular",'Casuística'!$N$3:$N$302,"=Combinada") | H30: =COUNTIFS('Casuística'!$H$3:$H$302,"=Ginecologia/Obstetrícia",'Casuística'!$N$3:$N$302,"=Combinada") | I30: =COUNTIFS('Casuística'!$H$3:$H$302,"=Neurocirurgia",'Casuística'!$N$3:$N$302,"=Combinada") | J30: =COUNTIFS('Casuística'!$H$3:$H$302,"=Oftalmologia",'Casuística'!$N$3:$N$302,"=Combinada") | K30: =COUNTIFS('Casuística'!$H$3:$H$302,"=ORL",'Casuística'!$N$3:$N$302,"=Combinada") | L30: =COUNTIFS('Casuística'!$H$3:$H$302,"=Ortopedia",'Casuística'!$N$3:$N$302,"=Combinada") | M30: =COUNTIFS('Casuística'!$H$3:$H$302,"=Urologia",'Casuística'!$N$3:$N$302,"=Combinada") | N30: =COUNTIFS('Casuística'!$H$3:$H$302,"=Fora do Bloco",'Casuística'!$N$3:$N$302,"=Combinada") | O30: =SUM(D30:N30)
B31: Sedoanalgesia | D31: =COUNTIFS('Casuística'!$H$3:$H$302,"=Cirurgia Geral",'Casuística'!$N$3:$N$302,"=Sedoanalgesia") | E31: =COUNTIFS('Casuística'!$H$3:$H$302,"=Cirurgia Pediátrica",'Casuística'!$N$3:$N$302,"=Sedoanalgesia") | F31: =COUNTIFS('Casuística'!$H$3:$H$302,"=Cirurgia Plástica",'Casuística'!$N$3:$N$302,"=Sedoanalgesia") | G31: =COUNTIFS('Casuística'!$H$3:$H$302,"=Cirurgia Vascular",'Casuística'!$N$3:$N$302,"=Sedoanalgesia") | H31: =COUNTIFS('Casuística'!$H$3:$H$302,"=Ginecologia/Obstetrícia",'Casuística'!$N$3:$N$302,"=Sedoanalgesia") | I31: =COUNTIFS('Casuística'!$H$3:$H$302,"=Neurocirurgia",'Casuística'!$N$3:$N$302,"=Sedoanalgesia") | J31: =COUNTIFS('Casuística'!$H$3:$H$302,"=Oftalmologia",'Casuística'!$N$3:$N$302,"=Sedoanalgesia") | K31: =COUNTIFS('Casuística'!$H$3:$H$302,"=ORL",'Casuística'!$N$3:$N$302,"=Sedoanalgesia") | L31: =COUNTIFS('Casuística'!$H$3:$H$302,"=Ortopedia",'Casuística'!$N$3:$N$302,"=Sedoanalgesia") | M31: =COUNTIFS('Casuística'!$H$3:$H$302,"=Urologia",'Casuística'!$N$3:$N$302,"=Sedoanalgesia") | N31: =COUNTIFS('Casuística'!$H$3:$H$302,"=Fora do Bloco",'Casuística'!$N$3:$N$302,"=Sedoanalgesia") | O31: =SUM(D31:N31)
B32: Monitorização (CAM) | D32: =COUNTIFS('Casuística'!$H$3:$H$302,"=Cirurgia Geral",'Casuística'!$N$3:$N$302,"=Monitorização (CAM)") | E32: =COUNTIFS('Casuística'!$H$3:$H$302,"=Cirurgia Pediátrica",'Casuística'!$N$3:$N$302,"=Monitorização (CAM)") | F32: =COUNTIFS('Casuística'!$H$3:$H$302,"=Cirurgia Plástica",'Casuística'!$N$3:$N$302,"=Monitorização (CAM)") | G32: =COUNTIFS('Casuística'!$H$3:$H$302,"=Cirurgia Vascular",'Casuística'!$N$3:$N$302,"=Monitorização (CAM)") | H32: =COUNTIFS('Casuística'!$H$3:$H$302,"=Ginecologia/Obstetrícia",'Casuística'!$N$3:$N$302,"=Monitorização (CAM)") | I32: =COUNTIFS('Casuística'!$H$3:$H$302,"=Neurocirurgia",'Casuística'!$N$3:$N$302,"=Monitorização (CAM)") | J32: =COUNTIFS('Casuística'!$H$3:$H$302,"=Oftalmologia",'Casuística'!$N$3:$N$302,"=Monitorização (CAM)") | K32: =COUNTIFS('Casuística'!$H$3:$H$302,"=ORL",'Casuística'!$N$3:$N$302,"=Monitorização (CAM)") | L32: =COUNTIFS('Casuística'!$H$3:$H$302,"=Ortopedia",'Casuística'!$N$3:$N$302,"=Monitorização (CAM)") | M32: =COUNTIFS('Casuística'!$H$3:$H$302,"=Urologia",'Casuística'!$N$3:$N$302,"=Monitorização (CAM)") | N32: =COUNTIFS('Casuística'!$H$3:$H$302,"=Fora do Bloco",'Casuística'!$N$3:$N$302,"=Monitorização (CAM)") | O32: =SUM(D32:N32)
A33: DURAÇÃO | B33: < 60 minutos | D33: =COUNTIFS('Casuística'!$H$3:$H$302,"=Cirurgia Geral",'Casuística'!$M$3:$M$302,"=< 1h") | E33: =COUNTIFS('Casuística'!$H$3:$H$302,"=Cirurgia Pediátrica",'Casuística'!$M$3:$M$302,"=< 1h") | F33: =COUNTIFS('Casuística'!$H$3:$H$302,"=Cirurgia Plástica",'Casuística'!$M$3:$M$302,"=< 1h") | G33: =COUNTIFS('Casuística'!$H$3:$H$302,"=Cirurgia Vascular",'Casuística'!$M$3:$M$302,"=< 1h") | H33: =COUNTIFS('Casuística'!$H$3:$H$302,"=Ginecologia/Obstetrícia",'Casuística'!$M$3:$M$302,"=< 1h") | I33: =COUNTIFS('Casuística'!$H$3:$H$302,"=Neurocirurgia",'Casuística'!$M$3:$M$302,"=< 1h") | J33: =COUNTIFS('Casuística'!$H$3:$H$302,"=Oftalmologia",'Casuística'!$M$3:$M$302,"=< 1h") | K33: =COUNTIFS('Casuística'!$H$3:$H$302,"=ORL",'Casuística'!$M$3:$M$302,"=< 1h") | L33: =COUNTIFS('Casuística'!$H$3:$H$302,"=Ortopedia",'Casuística'!$M$3:$M$302,"=< 1h") | M33: =COUNTIFS('Casuística'!$H$3:$H$302,"=Urologia",'Casuística'!$M$3:$M$302,"=< 1h") | N33: =COUNTIFS('Casuística'!$H$3:$H$302,"=Fora do Bloco",'Casuística'!$M$3:$M$302,"=< 1h") | O33: =SUM(D33:N33)
B34: 60 minutos a 3 horas | D34: =COUNTIFS('Casuística'!$H$3:$H$302,"=Cirurgia Geral",'Casuística'!$M$3:$M$302,"=1 a 3 horas") | E34: =COUNTIFS('Casuística'!$H$3:$H$302,"=Cirurgia Pediátrica",'Casuística'!$M$3:$M$302,"=1 a 3 horas") | F34: =COUNTIFS('Casuística'!$H$3:$H$302,"=Cirurgia Plástica",'Casuística'!$M$3:$M$302,"=1 a 3 horas") | G34: =COUNTIFS('Casuística'!$H$3:$H$302,"=Cirurgia Vascular",'Casuística'!$M$3:$M$302,"=1 a 3 horas") | H34: =COUNTIFS('Casuística'!$H$3:$H$302,"=Ginecologia/Obstetrícia",'Casuística'!$M$3:$M$302,"=1 a 3 horas") | I34: =COUNTIFS('Casuística'!$H$3:$H$302,"=Neurocirurgia",'Casuística'!$M$3:$M$302,"=1 a 3 horas") | J34: =COUNTIFS('Casuística'!$H$3:$H$302,"=Oftalmologia",'Casuística'!$M$3:$M$302,"=1 a 3 horas") | K34: =COUNTIFS('Casuística'!$H$3:$H$302,"=ORL",'Casuística'!$M$3:$M$302,"=1 a 3 horas") | L34: =COUNTIFS('Casuística'!$H$3:$H$302,"=Ortopedia",'Casuística'!$M$3:$M$302,"=1 a 3 horas") | M34: =COUNTIFS('Casuística'!$H$3:$H$302,"=Urologia",'Casuística'!$M$3:$M$302,"=1 a 3 horas") | N34: =COUNTIFS('Casuística'!$H$3:$H$302,"=Fora do Bloco",'Casuística'!$M$3:$M$302,"=1 a 3 horas") | O34: =SUM(D34:N34)
B35: > 3 horas | D35: =COUNTIFS('Casuística'!$H$3:$H$302,"=Cirurgia Geral",'Casuística'!$M$3:$M$302,"=> 3 horas") | E35: =COUNTIFS('Casuística'!$H$3:$H$302,"=Cirurgia Pediátrica",'Casuística'!$M$3:$M$302,"=> 3 horas") | F35: =COUNTIFS('Casuística'!$H$3:$H$302,"=Cirurgia Plástica",'Casuística'!$M$3:$M$302,"=> 3 horas") | G35: =COUNTIFS('Casuística'!$H$3:$H$302,"=Cirurgia Vascular",'Casuística'!$M$3:$M$302,"=> 3 horas") | H35: =COUNTIFS('Casuística'!$H$3:$H$302,"=Ginecologia/Obstetrícia",'Casuística'!$M$3:$M$302,"=> 3 horas") | I35: =COUNTIFS('Casuística'!$H$3:$H$302,"=Neurocirurgia",'Casuística'!$M$3:$M$302,"=> 3 horas") | J35: =COUNTIFS('Casuística'!$H$3:$H$302,"=Oftalmologia",'Casuística'!$M$3:$M$302,"=> 3 horas") | K35: =COUNTIFS('Casuística'!$H$3:$H$302,"=ORL",'Casuística'!$M$3:$M$302,"=> 3 horas") | L35: =COUNTIFS('Casuística'!$H$3:$H$302,"=Ortopedia",'Casuística'!$M$3:$M$302,"=> 3 horas") | M35: =COUNTIFS('Casuística'!$H$3:$H$302,"=Urologia",'Casuística'!$M$3:$M$302,"=> 3 horas") | N35: =COUNTIFS('Casuística'!$H$3:$H$302,"=Fora do Bloco",'Casuística'!$M$3:$M$302,"=> 3 horas") | O35: =SUM(D35:N35)
A37: Tabela 19. Casuística no Serviço de Urgência

Sheet Listas
A1: Opções das caixas de escolha (acrescenta valores no fim de cada coluna)
A2: Grupo Etário | B2: Sexo | C2: ASA | D2: Regime | E2: Especialidade | F2: Local fora do BO | G2: Duração | H2: Técnica Anestésica | I2: Anestesia Geral | J2: Neuroeixo | K2: Bloqueio Periférico | L2: Método | M2: Intuito | N2: Sucesso | O2: Monitorização | P2: Tipo VA | Q2: Técnica VA | R2: Laringoscópio e Adjuvantes | S2: Cormack-Lehane | T2: Linha Arterial | U2: CVC | V2: Destino | W2: Sim/Não
A3: < 24 horas | B3: Feminino | C3: I | D3: Urgência | E3: Cirurgia Geral | F3: Gastroenterologia | G3: < 1h | H3: Geral | I3: Balanceada | J3: Bloqueio Subaracnoideu | K3: Plano do Transverso do Abdómen (TAP) | L3: Ecoguiado | M3: Analgésico | N3: Sucesso | O3: ASA | P3: Ventilação Espontânea | Q3: Laringoscopia direta | R3: Macintosh | S3: Fácil (CL 1-2) | T3: Radial | U3: Jugular interna | V3: UCPA | W3: Sim
A4: 24 horas a 1 mês | B4: Masculino | C4: II | D4: Internamento (programada) | E4: Cirurgia Pediátrica | F4: UCI Pediátrica | G4: 1 a 3 horas | H4: Regional | I4: Endovenosa | J4: Epidural Lombar | K4: Bainha dos Retos | L4: Referências Anatómicas | M4: Anestésico | N4: Insucesso | O4: ASA + BIS | P4: Máscara Facial | Q4: Videolaringoscopia | R4: Macintosh + Condutor | S4: Difícil (CL 3-4) | T4: Umeral | U4: Subclávia | V4: SO | W4: Não
A5: > 1 mês a 6 meses | C5: III | D5: Ambulatório (programada) | E5: Cirurgia Plástica | F5: UCI | G5: > 3 horas | H5: Combinada | I5: Inalatória | J5: Epidural Torácica | K5: Eretor da Espinha | N5: Observado | O5: ASA + TOF | P5: Máscara Laríngea | Q5: Fibroscopia | R5: Macintosh + Frova | T5: Femoral | U5: Femoral | V5: UCI
A6: > 6 meses a 4 anos | C6: IV | E6: Cirurgia Vascular | F6: Serviço de Urgência | H6: Sedoanalgesia | J6: Sequencial | K6: Plano Serratus Anterior | O6: ASA + PAI | P6: Intubação Orotraqueal | Q6: Fibroscopia vigil | R6: McCoy | T6: Cubital | U6: Axilar | V6: BUC
A7: > 4 anos a 12 anos | C7: V | E7: Ginecologia/Obstetrícia | F7: Imagiologia | H7: Monitorização (CAM) | K7: Paravertebral | O7: ASA + BIS + TOF | P7: Intubação Nasotraqueal | R7: Videolaringoscópio | T7: Não registado | U7: Não registado | V7: Enfermaria
A8: > 12 anos a 65 anos | C8: VI | E8: Neurocirurgia | F8: Enfermaria | K8: Plexo braquial - Interescalénico | O8: ASA + BIS + PAI | P8: Traqueostomia | R8: Videolaringoscópio + Condutor | V8: Óbito
A9: > 65 anos a 85 anos | E9: Oftalmologia | K9: Plexo braquial - Supraclavicular | O9: ASA + BIS + TOF + PAI | R9: i-Gel
A10: > 85 anos | E10: ORL | K10: Plexo braquial - Infraclavicular | O10: ASA + BIS + TOF + PAI + PVC | R10: LMA Supreme
E11: Ortopedia | K11: Plexo braquial - Axilar
E12: Urologia | K12: Fáscia Ilíaca
E13: Fora do Bloco | K13: Femoral
E14: Doente Crítico | K14: Ciático Poplíteu
K15: Canal dos adutores

Sheet Via Aérea
A1: Técnicas de abordagem da via aérea | D1: SUCESSO | E1: INSUCESSO | F1: OBSERVADO | G1: TOTAL
A2: DISPOSITIVO SUPRAGLÓTICO | B2: Máscara laríngea | D2: =COUNTIFS('Casuística'!$Z$3:$Z$302,"=Máscara Laríngea",'Casuística'!$AD$3:$AD$302,"=Sucesso") | E2: =COUNTIFS('Casuística'!$Z$3:$Z$302,"=Máscara Laríngea",'Casuística'!$AD$3:$AD$302,"=Insucesso") | F2: =COUNTIFS('Casuística'!$Z$3:$Z$302,"=Máscara Laríngea",'Casuística'!$AD$3:$AD$302,"=Observado") | G2: =COUNTIFS('Casuística'!$Z$3:$Z$302,"=Máscara Laríngea")
A3: INTUBAÇÃO OROTRAQUEAL | B3: Laringoscopia direta (Macintosh) | C3: Simples | D3: =COUNTIFS('Casuística'!$Z$3:$Z$302,"=Intubação Orotraqueal",'Casuística'!$AB$3:$AB$302,"=Macintosh",'Casuística'!$AD$3:$AD$302,"=Sucesso") | E3: =COUNTIFS('Casuística'!$Z$3:$Z$302,"=Intubação Orotraqueal",'Casuística'!$AB$3:$AB$302,"=Macintosh",'Casuística'!$AD$3:$AD$302,"=Insucesso") | F3: =COUNTIFS('Casuística'!$Z$3:$Z$302,"=Intubação Orotraqueal",'Casuística'!$AB$3:$AB$302,"=Macintosh",'Casuística'!$AD$3:$AD$302,"=Observado") | G3: =COUNTIFS('Casuística'!$Z$3:$Z$302,"=Intubação Orotraqueal",'Casuística'!$AB$3:$AB$302,"=Macintosh")
C4: Condutor | D4: =COUNTIFS('Casuística'!$Z$3:$Z$302,"=Intubação Orotraqueal",'Casuística'!$AB$3:$AB$302,"=Macintosh + Condutor",'Casuística'!$AD$3:$AD$302,"=Sucesso") | E4: =COUNTIFS('Casuística'!$Z$3:$Z$302,"=Intubação Orotraqueal",'Casuística'!$AB$3:$AB$302,"=Macintosh + Condutor",'Casuística'!$AD$3:$AD$302,"=Insucesso") | F4: =COUNTIFS('Casuística'!$Z$3:$Z$302,"=Intubação Orotraqueal",'Casuística'!$AB$3:$AB$302,"=Macintosh + Condutor",'Casuística'!$AD$3:$AD$302,"=Observado") | G4: =COUNTIFS('Casuística'!$Z$3:$Z$302,"=Intubação Orotraqueal",'Casuística'!$AB$3:$AB$302,"=Macintosh + Condutor")
C5: Frova | D5: =COUNTIFS('Casuística'!$Z$3:$Z$302,"=Intubação Orotraqueal",'Casuística'!$AB$3:$AB$302,"=Macintosh + Frova",'Casuística'!$AD$3:$AD$302,"=Sucesso") | E5: =COUNTIFS('Casuística'!$Z$3:$Z$302,"=Intubação Orotraqueal",'Casuística'!$AB$3:$AB$302,"=Macintosh + Frova",'Casuística'!$AD$3:$AD$302,"=Insucesso") | F5: =COUNTIFS('Casuística'!$Z$3:$Z$302,"=Intubação Orotraqueal",'Casuística'!$AB$3:$AB$302,"=Macintosh + Frova",'Casuística'!$AD$3:$AD$302,"=Observado") | G5: =COUNTIFS('Casuística'!$Z$3:$Z$302,"=Intubação Orotraqueal",'Casuística'!$AB$3:$AB$302,"=Macintosh + Frova")
B6: Laringoscopia direta (McCoy) | D6: =COUNTIFS('Casuística'!$Z$3:$Z$302,"=Intubação Orotraqueal",'Casuística'!$AB$3:$AB$302,"=McCoy",'Casuística'!$AD$3:$AD$302,"=Sucesso") | E6: =COUNTIFS('Casuística'!$Z$3:$Z$302,"=Intubação Orotraqueal",'Casuística'!$AB$3:$AB$302,"=McCoy",'Casuística'!$AD$3:$AD$302,"=Insucesso") | F6: =COUNTIFS('Casuística'!$Z$3:$Z$302,"=Intubação Orotraqueal",'Casuística'!$AB$3:$AB$302,"=McCoy",'Casuística'!$AD$3:$AD$302,"=Observado") | G6: =COUNTIFS('Casuística'!$Z$3:$Z$302,"=Intubação Orotraqueal",'Casuística'!$AB$3:$AB$302,"=McCoy")
B7: Videolaringoscopia | C7: Simples | D7: =COUNTIFS('Casuística'!$Z$3:$Z$302,"=Intubação Orotraqueal",'Casuística'!$AB$3:$AB$302,"=Videolaringoscópio",'Casuística'!$AD$3:$AD$302,"=Sucesso") | E7: =COUNTIFS('Casuística'!$Z$3:$Z$302,"=Intubação Orotraqueal",'Casuística'!$AB$3:$AB$302,"=Videolaringoscópio",'Casuística'!$AD$3:$AD$302,"=Insucesso") | F7: =COUNTIFS('Casuística'!$Z$3:$Z$302,"=Intubação Orotraqueal",'Casuística'!$AB$3:$AB$302,"=Videolaringoscópio",'Casuística'!$AD$3:$AD$302,"=Observado") | G7: =COUNTIFS('Casuística'!$Z$3:$Z$302,"=Intubação Orotraqueal",'Casuística'!$AB$3:$AB$302,"=Videolaringoscópio")
C8: Condutor | D8: =COUNTIFS('Casuística'!$Z$3:$Z$302,"=Intubação Orotraqueal",'Casuística'!$AB$3:$AB$302,"=Videolaringoscópio + Condutor",'Casuística'!$AD$3:$AD$302,"=Sucesso") | E8: =COUNTIFS('Casuística'!$Z$3:$Z$302,"=Intubação Orotraqueal",'Casuística'!$AB$3:$AB$302,"=Videolaringoscópio + Condutor",'Casuística'!$AD$3:$AD$302,"=Insucesso") | F8: =COUNTIFS('Casuística'!$Z$3:$Z$302,"=Intubação Orotraqueal",'Casuística'!$AB$3:$AB$302,"=Videolaringoscópio + Condutor",'Casuística'!$AD$3:$AD$302,"=Observado") | G8: =COUNTIFS('Casuística'!$Z$3:$Z$302,"=Intubação Orotraqueal",'Casuística'!$AB$3:$AB$302,"=Videolaringoscópio + Condutor")
B9: Fibroscopia | D9: =COUNTIFS('Casuística'!$Z$3:$Z$302,"=Intubação Orotraqueal",'Casuística'!$AA$3:$AA$302,"=Fibroscopia*",'Casuística'!$AD$3:$AD$302,"=Sucesso") | E9: =COUNTIFS('Casuística'!$Z$3:$Z$302,"=Intubação Orotraqueal",'Casuística'!$AA$3:$AA$302,"=Fibroscopia*",'Casuística'!$AD$3:$AD$302,"=Insucesso") | F9: =COUNTIFS('Casuística'!$Z$3:$Z$302,"=Intubação Orotraqueal",'Casuística'!$AA$3:$AA$302,"=Fibroscopia*",'Casuística'!$AD$3:$AD$302,"=Observado") | G9: =COUNTIFS('Casuística'!$Z$3:$Z$302,"=Intubação Orotraqueal",'Casuística'!$AA$3:$AA$302,"=Fibroscopia*")
B10: Técnica não registada | D10: =COUNTIFS('Casuística'!$Z$3:$Z$302,"=Intubação Orotraqueal",'Casuística'!$AA$3:$AA$302,"",'Casuística'!$AD$3:$AD$302,"=Sucesso") | E10: =COUNTIFS('Casuística'!$Z$3:$Z$302,"=Intubação Orotraqueal",'Casuística'!$AA$3:$AA$302,"",'Casuística'!$AD$3:$AD$302,"=Insucesso") | F10: =COUNTIFS('Casuística'!$Z$3:$Z$302,"=Intubação Orotraqueal",'Casuística'!$AA$3:$AA$302,"",'Casuística'!$AD$3:$AD$302,"=Observado") | G10: =COUNTIFS('Casuística'!$Z$3:$Z$302,"=Intubação Orotraqueal",'Casuística'!$AA$3:$AA$302,"")
A11: INTUBAÇÃO NASOTRAQUEAL | B11: Laringoscopia direta | D11: =COUNTIFS('Casuística'!$Z$3:$Z$302,"=Intubação Nasotraqueal",'Casuística'!$AA$3:$AA$302,"=Laringoscopia direta",'Casuística'!$AD$3:$AD$302,"=Sucesso") | E11: =COUNTIFS('Casuística'!$Z$3:$Z$302,"=Intubação Nasotraqueal",'Casuística'!$AA$3:$AA$302,"=Laringoscopia direta",'Casuística'!$AD$3:$AD$302,"=Insucesso") | F11: =COUNTIFS('Casuística'!$Z$3:$Z$302,"=Intubação Nasotraqueal",'Casuística'!$AA$3:$AA$302,"=Laringoscopia direta",'Casuística'!$AD$3:$AD$302,"=Observado") | G11: =COUNTIFS('Casuística'!$Z$3:$Z$302,"=Intubação Nasotraqueal",'Casuística'!$AA$3:$AA$302,"=Laringoscopia direta")
B12: Videolaringoscopia | D12: =COUNTIFS('Casuística'!$Z$3:$Z$302,"=Intubação Nasotraqueal",'Casuística'!$AA$3:$AA$302,"=Videolaringoscopia",'Casuística'!$AD$3:$AD$302,"=Sucesso") | E12: =COUNTIFS('Casuística'!$Z$3:$Z$302,"=Intubação Nasotraqueal",'Casuística'!$AA$3:$AA$302,"=Videolaringoscopia",'Casuística'!$AD$3:$AD$302,"=Insucesso") | F12: =COUNTIFS('Casuística'!$Z$3:$Z$302,"=Intubação Nasotraqueal",'Casuística'!$AA$3:$AA$302,"=Videolaringoscopia",'Casuística'!$AD$3:$AD$302,"=Observado") | G12: =COUNTIFS('Casuística'!$Z$3:$Z$302,"=Intubação Nasotraqueal",'Casuística'!$AA$3:$AA$302,"=Videolaringoscopia")
B13: Fibroscopia | D13: =COUNTIFS('Casuística'!$Z$3:$Z$302,"=Intubação Nasotraqueal",'Casuística'!$AA$3:$AA$302,"=Fibroscopia*",'Casuística'!$AD$3:$AD$302,"=Sucesso") | E13: =COUNTIFS('Casuística'!$Z$3:$Z$302,"=Intubação Nasotraqueal",'Casuística'!$AA$3:$AA$302,"=Fibroscopia*",'Casuística'!$AD$3:$AD$302,"=Insucesso") | F13: =COUNTIFS('Casuística'!$Z$3:$Z$302,"=Intubação Nasotraqueal",'Casuística'!$AA$3:$AA$302,"=Fibroscopia*",'Casuística'!$AD$3:$AD$302,"=Observado") | G13: =COUNTIFS('Casuística'!$Z$3:$Z$302,"=Intubação Nasotraqueal",'Casuística'!$AA$3:$AA$302,"=Fibroscopia*")
A14: TOTAL | D14: =SUM(D2:D13) | E14: =SUM(E2:E13) | F14: =SUM(F2:F13) | G14: =SUM(G2:G13)
A16: Via aérea difícil (Cormack-Lehane 3-4) | G16: =COUNTIFS('Casuística'!$AC$3:$AC$302,"=Difícil (CL 3-4)")
A17: Ventilação espontânea (sem dispositivo) | G17: =COUNTIFS('Casuística'!$Z$3:$Z$302,"=Ventilação Espontânea")

Sheet Anestesia Regional
A1: Técnicas de anestesia regional | C1: Finalidade Analgésica | D1: Finalidade Anestésica | E1: Sucesso | F1: Insucesso | G1: Observado | H1: TOTAL
A2: NERVOS PERIFÉRICOS | H2: =SUM(H3:H15)
A3: TÓRAX E ABDÓMEN | B3: Plano do Transverso do Abdómen (TAP) | C3: =COUNTIFS('Casuística'!$T$3:$T$302,"=Plano do Transverso do Abdómen (TAP)",'Casuística'!$W$3:$W$302,"=Analgésico")+COUNTIFS('Casuística'!$U$3:$U$302,"=Plano do Transverso do Abdómen (TAP)",'Casuística'!$W$3:$W$302,"=Analgésico") | D3: =COUNTIFS('Casuística'!$T$3:$T$302,"=Plano do Transverso do Abdómen (TAP)",'Casuística'!$W$3:$W$302,"=Anestésico")+COUNTIFS('Casuística'!$U$3:$U$302,"=Plano do Transverso do Abdómen (TAP)",'Casuística'!$W$3:$W$302,"=Anestésico") | E3: =COUNTIFS('Casuística'!$T$3:$T$302,"=Plano do Transverso do Abdómen (TAP)",'Casuística'!$X$3:$X$302,"=Sucesso")+COUNTIFS('Casuística'!$U$3:$U$302,"=Plano do Transverso do Abdómen (TAP)",'Casuística'!$X$3:$X$302,"=Sucesso") | F3: =COUNTIFS('Casuística'!$T$3:$T$302,"=Plano do Transverso do Abdómen (TAP)",'Casuística'!$X$3:$X$302,"=Insucesso")+COUNTIFS('Casuística'!$U$3:$U$302,"=Plano do Transverso do Abdómen (TAP)",'Casuística'!$X$3:$X$302,"=Insucesso") | G3: =COUNTIFS('Casuística'!$T$3:$T$302,"=Plano do Transverso do Abdómen (TAP)",'Casuística'!$X$3:$X$302,"=Observado")+COUNTIFS('Casuística'!$U$3:$U$302,"=Plano do Transverso do Abdómen (TAP)",'Casuística'!$X$3:$X$302,"=Observado") | H3: =COUNTIFS('Casuística'!$T$3:$T$302,"=Plano do Transverso do Abdómen (TAP)")+COUNTIFS('Casuística'!$U$3:$U$302,"=Plano do Transverso do Abdómen (TAP)")
B4: Bainha dos Retos | C4: =COUNTIFS('Casuística'!$T$3:$T$302,"=Bainha dos Retos",'Casuística'!$W$3:$W$302,"=Analgésico")+COUNTIFS('Casuística'!$U$3:$U$302,"=Bainha dos Retos",'Casuística'!$W$3:$W$302,"=Analgésico") | D4: =COUNTIFS('Casuística'!$T$3:$T$302,"=Bainha dos Retos",'Casuística'!$W$3:$W$302,"=Anestésico")+COUNTIFS('Casuística'!$U$3:$U$302,"=Bainha dos Retos",'Casuística'!$W$3:$W$302,"=Anestésico") | E4: =COUNTIFS('Casuística'!$T$3:$T$302,"=Bainha dos Retos",'Casuística'!$X$3:$X$302,"=Sucesso")+COUNTIFS('Casuística'!$U$3:$U$302,"=Bainha dos Retos",'Casuística'!$X$3:$X$302,"=Sucesso") | F4: =COUNTIFS('Casuística'!$T$3:$T$302,"=Bainha dos Retos",'Casuística'!$X$3:$X$302,"=Insucesso")+COUNTIFS('Casuística'!$U$3:$U$302,"=Bainha dos Retos",'Casuística'!$X$3:$X$302,"=Insucesso") | G4: =COUNTIFS('Casuística'!$T$3:$T$302,"=Bainha dos Retos",'Casuística'!$X$3:$X$302,"=Observado")+COUNTIFS('Casuística'!$U$3:$U$302,"=Bainha dos Retos",'Casuística'!$X$3:$X$302,"=Observado") | H4: =COUNTIFS('Casuística'!$T$3:$T$302,"=Bainha dos Retos")+COUNTIFS('Casuística'!$U$3:$U$302,"=Bainha dos Retos")
B5: Eretor da Espinha | C5: =COUNTIFS('Casuística'!$T$3:$T$302,"=Eretor da Espinha",'Casuística'!$W$3:$W$302,"=Analgésico")+COUNTIFS('Casuística'!$U$3:$U$302,"=Eretor da Espinha",'Casuística'!$W$3:$W$302,"=Analgésico") | D5: =COUNTIFS('Casuística'!$T$3:$T$302,"=Eretor da Espinha",'Casuística'!$W$3:$W$302,"=Anestésico")+COUNTIFS('Casuística'!$U$3:$U$302,"=Eretor da Espinha",'Casuística'!$W$3:$W$302,"=Anestésico") | E5: =COUNTIFS('Casuística'!$T$3:$T$302,"=Eretor da Espinha",'Casuística'!$X$3:$X$302,"=Sucesso")+COUNTIFS('Casuística'!$U$3:$U$302,"=Eretor da Espinha",'Casuística'!$X$3:$X$302,"=Sucesso") | F5: =COUNTIFS('Casuística'!$T$3:$T$302,"=Eretor da Espinha",'Casuística'!$X$3:$X$302,"=Insucesso")+COUNTIFS('Casuística'!$U$3:$U$302,"=Eretor da Espinha",'Casuística'!$X$3:$X$302,"=Insucesso") | G5: =COUNTIFS('Casuística'!$T$3:$T$302,"=Eretor da Espinha",'Casuística'!$X$3:$X$302,"=Observado")+COUNTIFS('Casuística'!$U$3:$U$302,"=Eretor da Espinha",'Casuística'!$X$3:$X$302,"=Observado") | H5: =COUNTIFS('Casuística'!$T$3:$T$302,"=Eretor da Espinha")+COUNTIFS('Casuística'!$U$3:$U$302,"=Eretor da Espinha")
B6: Plano Serratus Anterior | C6: =COUNTIFS('Casuística'!$T$3:$T$302,"=Plano Serratus Anterior",'Casuística'!$W$3:$W$302,"=Analgésico")+COUNTIFS('Casuística'!$U$3:$U$302,"=Plano Serratus Anterior",'Casuística'!$W$3:$W$302,"=Analgésico") | D6: =COUNTIFS('Casuística'!$T$3:$T$302,"=Plano Serratus Anterior",'Casuística'!$W$3:$W$302,"=Anestésico")+COUNTIFS('Casuística'!$U$3:$U$302,"=Plano Serratus Anterior",'Casuística'!$W$3:$W$302,"=Anestésico") | E6: =COUNTIFS('Casuística'!$T$3:$T$302,"=Plano Serratus Anterior",'Casuística'!$X$3:$X$302,"=Sucesso")+COUNTIFS('Casuística'!$U$3:$U$302,"=Plano Serratus Anterior",'Casuística'!$X$3:$X$302,"=Sucesso") | F6: =COUNTIFS('Casuística'!$T$3:$T$302,"=Plano Serratus Anterior",'Casuística'!$X$3:$X$302,"=Insucesso")+COUNTIFS('Casuística'!$U$3:$U$302,"=Plano Serratus Anterior",'Casuística'!$X$3:$X$302,"=Insucesso") | G6: =COUNTIFS('Casuística'!$T$3:$T$302,"=Plano Serratus Anterior",'Casuística'!$X$3:$X$302,"=Observado")+COUNTIFS('Casuística'!$U$3:$U$302,"=Plano Serratus Anterior",'Casuística'!$X$3:$X$302,"=Observado") | H6: =COUNTIFS('Casuística'!$T$3:$T$302,"=Plano Serratus Anterior")+COUNTIFS('Casuística'!$U$3:$U$302,"=Plano Serratus Anterior")
B7: Paravertebral | C7: =COUNTIFS('Casuística'!$T$3:$T$302,"=Paravertebral",'Casuística'!$W$3:$W$302,"=Analgésico")+COUNTIFS('Casuística'!$U$3:$U$302,"=Paravertebral",'Casuística'!$W$3:$W$302,"=Analgésico") | D7: =COUNTIFS('Casuística'!$T$3:$T$302,"=Paravertebral",'Casuística'!$W$3:$W$302,"=Anestésico")+COUNTIFS('Casuística'!$U$3:$U$302,"=Paravertebral",'Casuística'!$W$3:$W$302,"=Anestésico") | E7: =COUNTIFS('Casuística'!$T$3:$T$302,"=Paravertebral",'Casuística'!$X$3:$X$302,"=Sucesso")+COUNTIFS('Casuística'!$U$3:$U$302,"=Paravertebral",'Casuística'!$X$3:$X$302,"=Sucesso") | F7: =COUNTIFS('Casuística'!$T$3:$T$302,"=Paravertebral",'Casuística'!$X$3:$X$302,"=Insucesso")+COUNTIFS('Casuística'!$U$3:$U$302,"=Paravertebral",'Casuística'!$X$3:$X$302,"=Insucesso") | G7: =COUNTIFS('Casuística'!$T$3:$T$302,"=Paravertebral",'Casuística'!$X$3:$X$302,"=Observado")+COUNTIFS('Casuística'!$U$3:$U$302,"=Paravertebral",'Casuística'!$X$3:$X$302,"=Observado") | H7: =COUNTIFS('Casuística'!$T$3:$T$302,"=Paravertebral")+COUNTIFS('Casuística'!$U$3:$U$302,"=Paravertebral")
A8: MEMBRO SUPERIOR | B8: Plexo braquial - Interescalénico | C8: =COUNTIFS('Casuística'!$T$3:$T$302,"=Plexo braquial - Interescalénico",'Casuística'!$W$3:$W$302,"=Analgésico")+COUNTIFS('Casuística'!$U$3:$U$302,"=Plexo braquial - Interescalénico",'Casuística'!$W$3:$W$302,"=Analgésico") | D8: =COUNTIFS('Casuística'!$T$3:$T$302,"=Plexo braquial - Interescalénico",'Casuística'!$W$3:$W$302,"=Anestésico")+COUNTIFS('Casuística'!$U$3:$U$302,"=Plexo braquial - Interescalénico",'Casuística'!$W$3:$W$302,"=Anestésico") | E8: =COUNTIFS('Casuística'!$T$3:$T$302,"=Plexo braquial - Interescalénico",'Casuística'!$X$3:$X$302,"=Sucesso")+COUNTIFS('Casuística'!$U$3:$U$302,"=Plexo braquial - Interescalénico",'Casuística'!$X$3:$X$302,"=Sucesso") | F8: =COUNTIFS('Casuística'!$T$3:$T$302,"=Plexo braquial - Interescalénico",'Casuística'!$X$3:$X$302,"=Insucesso")+COUNTIFS('Casuística'!$U$3:$U$302,"=Plexo braquial - Interescalénico",'Casuística'!$X$3:$X$302,"=Insucesso") | G8: =COUNTIFS('Casuística'!$T$3:$T$302,"=Plexo braquial - Interescalénico",'Casuística'!$X$3:$X$302,"=Observado")+COUNTIFS('Casuística'!$U$3:$U$302,"=Plexo braquial - Interescalénico",'Casuística'!$X$3:$X$302,"=Observado") | H8: =COUNTIFS('Casuística'!$T$3:$T$302,"=Plexo braquial - Interescalénico")+COUNTIFS('Casuística'!$U$3:$U$302,"=Plexo braquial - Interescalénico")
